File: Bunching_Max_feb2021_Full.csv
,Modulus of elasticity – Inner – Warp (MPa),Modulus of elasticity – Inner – Weft (MPa),Shear modulus - Inner (MPa),Modulus of elasticity – Outer – Warp (MPa),Modulus of elasticity – Outer – Weft (MPa),Shear modulus - Outer (MPa),Friction coefficient,Axial Load (N/mm^2),Pre-strain (%),sample,Bunching (mm)
0,100,180,3.128,150,103,0.484,0.2,3.00E-05,Inside jacket 1.6%,sample-10,29.79763793
6,100,340,3.128,70,70,1.79,0.14,6.60E-05,Outside jacket 0.5%,sample-1005,0.988150675
12,100,340,3.128,70,70,1.79,0.2,6.60E-05,Outside jacket 0.5%,sample-1011,0.956644798
18,100,340,3.128,90,103,0.484,0.14,6.60E-05,Outside jacket 0.5%,sample-1017,1.220539521
24,100,340,3.128,90,103,0.484,0.2,6.60E-05,Outside jacket 0.5%,sample-1023,1.173699505
30,100,340,3.128,90,103,1.79,0.14,6.60E-05,Outside jacket 0.5%,sample-1029,1.048486152
36,100,340,3.128,90,103,1.79,0.2,6.60E-05,Outside jacket 0.5%,sample-1035,0.990916506
42,100,340,3.128,90,250,0.484,0.14,6.60E-05,Outside jacket 0.5%,sample-1041,4.364236477
48,100,340,3.128,90,250,0.484,0.2,6.60E-05,Outside jacket 0.5%,sample-1047,3.433103853
54,100,340,3.128,90,250,1.79,0.14,6.60E-05,Outside jacket 0.5%,sample-1053,3.954498929
60,100,340,3.128,90,250,1.79,0.2,6.60E-05,Outside jacket 0.5%,sample-1059,6.358121832
66,100,340,3.128,90,70,0.484,0.14,6.60E-05,Outside jacket 0.5%,sample-1065,0.793180525
72,100,340,3.128,90,70,0.484,0.2,6.60E-05,Outside jacket 0.5%,sample-1071,0.855363383
78,100,340,3.128,90,70,1.79,0.14,6.60E-05,Outside jacket 0.5%,sample-1077,0.732129057
84,100,340,3.128,90,70,1.79,0.2,6.60E-05,Outside jacket 0.5%,sample-1083,1.308448313
90,100,340,3.88,150,103,0.484,0.14,6.60E-05,Outside jacket 0.5%,sample-1089,0.772212263
96,100,340,3.88,150,103,0.484,0.2,6.60E-05,Outside jacket 0.5%,sample-1095,0.546458664
102,100,340,3.88,150,103,1.79,0.14,6.60E-05,Inside jacket 0.44%,sample-1100,0.499527395
108,100,340,3.88,150,103,1.79,0.2,6.60E-05,Inside jacket 0.44%,sample-1106,0.496075957
114,100,340,3.88,150,250,0.484,0.14,6.60E-05,Inside jacket 0.44%,sample-1112,0.786526839
120,100,340,3.88,150,250,0.484,0.2,6.60E-05,Inside jacket 0.44%,sample-1118,0.678165941
126,100,340,3.88,150,250,1.79,0.14,6.60E-05,Inside jacket 0.44%,sample-1124,0.513169633
132,100,340,3.88,150,250,1.79,0.2,6.60E-05,Inside jacket 0.44%,sample-1130,0.651718371
138,100,340,3.88,150,70,0.484,0.14,6.60E-05,Inside jacket 0.44%,sample-1136,0.525466905
144,100,340,3.88,150,70,0.484,0.2,6.60E-05,Inside jacket 0.44%,sample-1142,0.578492952
150,100,340,3.88,150,70,1.79,0.14,6.60E-05,Inside jacket 0.44%,sample-1148,0.501368394
156,100,340,3.88,150,70,1.79,0.2,6.60E-05,Inside jacket 0.44%,sample-1154,0.474618513
162,100,340,3.88,70,103,0.484,0.14,6.60E-05,Inside jacket 0.44%,sample-1160,0.820887884
168,100,340,3.88,70,103,0.484,0.2,6.60E-05,Inside jacket 0.44%,sample-1166,0.852332086
174,100,340,3.88,70,103,1.79,0.14,6.60E-05,Inside jacket 0.44%,sample-1172,0.786704318
180,100,340,3.88,70,103,1.79,0.2,6.60E-05,Inside jacket 0.44%,sample-1178,0.853714287
186,100,340,3.88,70,70,0.484,0.14,6.60E-05,Inside jacket 1.6%,sample-1207,12.44405632
192,100,340,3.88,70,70,0.484,0.2,6.60E-05,Inside jacket 1.6%,sample-1213,22.21527341
198,100,340,3.88,70,70,1.79,0.14,6.60E-05,Inside jacket 1.6%,sample-1219,14.65375311
204,100,340,3.88,70,70,1.79,0.2,6.60E-05,Inside jacket 1.6%,sample-1225,21.83195873
210,100,340,3.88,90,103,0.484,0.14,6.60E-05,Inside jacket 1.6%,sample-1231,13.72098698
216,100,340,3.88,90,103,0.484,0.2,6.60E-05,Inside jacket 1.6%,sample-1237,14.38784505
222,100,340,3.88,90,103,1.79,0.14,3.00E-05,Outside jacket 0.5%,sample-1242,0.801175757
228,100,340,3.88,90,103,1.79,0.2,3.00E-05,Outside jacket 0.5%,sample-1248,0.903581661
234,100,340,3.88,90,250,0.484,0.14,3.00E-05,Inside jacket 0.44%,sample-1253,1.809738972
240,100,340,3.88,90,250,0.484,0.2,6.60E-05,Inside jacket 1.6%,sample-1261,6.369863635
246,100,340,3.88,90,250,1.79,0.14,6.60E-05,Inside jacket 1.6%,sample-1267,18.43498506
252,100,340,3.88,90,250,1.79,0.2,3.00E-05,Outside jacket 0.5%,sample-1272,8.457988413
258,100,180,3.128,70,70,0.484,0.14,6.60E-05,Inside jacket 0.44%,sample-128,0.893176612
264,100,340,3.88,90,70,0.484,0.2,6.60E-05,Inside jacket 0.44%,sample-1286,0.731092998
270,100,180,3.128,150,103,0.484,0.2,6.60E-05,Inside jacket 1.6%,sample-13,31.84138519
276,140,180,3.128,150,103,0.484,0.14,6.60E-05,Inside jacket 0.44%,sample-1304,0.372280198
282,140,180,3.128,150,103,0.484,0.2,6.60E-05,Inside jacket 0.44%,sample-1310,0.424439086
288,140,180,3.128,150,103,1.79,0.2,3.00E-05,Inside jacket 1.6%,sample-1318,20.70797629
294,140,180,3.128,150,250,0.484,0.14,3.00E-05,Outside jacket 0.5%,sample-1326,0.83744629
300,140,180,3.128,150,250,0.484,0.2,3.00E-05,Inside jacket 0.44%,sample-1331,0.441156677
306,140,180,3.128,150,250,1.79,0.14,6.60E-05,Inside jacket 1.6%,sample-1339,20.2363772
312,140,180,3.128,150,250,1.79,0.2,6.60E-05,Inside jacket 0.44%,sample-1346,0.330146959
318,140,180,3.128,150,70,0.484,0.14,6.60E-05,Inside jacket 0.44%,sample-1352,0.401398676
324,140,180,3.128,150,70,1.79,0.14,3.00E-05,Inside jacket 0.44%,sample-1361,0.434899407
330,140,180,3.128,150,70,1.79,0.2,6.60E-05,Outside jacket 0.5%,sample-1371,3.031905957
336,140,180,3.128,70,103,0.484,0.2,3.00E-05,Inside jacket 0.44%,sample-1379,0.447474071
342,140,180,3.128,70,103,1.79,0.14,3.00E-05,Inside jacket 1.6%,sample-1384,31.89864345
348,100,180,3.128,70,70,1.79,0.14,6.60E-05,Inside jacket 1.6%,sample-139,37.12391379
354,100,180,3.128,150,103,0.484,0.2,6.60E-05,Inside jacket 0.44%,sample-14,0.679977996
360,140,180,3.128,70,70,0.484,0.14,3.00E-05,Outside jacket 0.5%,sample-1422,13.7198994
366,100,180,3.128,70,70,1.79,0.2,3.00E-05,Inside jacket 0.44%,sample-143,0.727565851
372,140,180,3.128,70,70,1.79,0.14,6.60E-05,Inside jacket 1.6%,sample-1435,38.65967523
378,140,180,3.128,70,70,1.79,0.2,6.60E-05,Inside jacket 0.44%,sample-1442,0.543161724
384,140,180,3.128,90,103,0.484,0.2,3.00E-05,Inside jacket 1.6%,sample-1450,21.46224325
390,140,180,3.128,90,103,1.79,0.14,6.60E-05,Inside jacket 1.6%,sample-1459,27.71527052
396,140,180,3.128,90,103,1.79,0.2,6.60E-05,Inside jacket 0.44%,sample-1466,0.599623113
402,140,180,3.128,90,250,0.484,0.2,3.00E-05,Inside jacket 0.44%,sample-1475,4.553570713
408,140,180,3.128,90,250,1.79,0.14,3.00E-05,Inside jacket 1.6%,sample-1480,47.29008967
414,100,180,3.128,90,103,0.484,0.14,3.00E-05,Inside jacket 0.44%,sample-149,0.738572563
420,140,180,3.128,90,70,0.484,0.14,6.60E-05,Outside jacket 0.5%,sample-1497,8.477361572
426,140,180,3.128,90,70,0.484,0.2,6.60E-05,Outside jacket 0.5%,sample-1503,6.388954445
432,100,180,3.128,90,103,0.484,0.14,6.60E-05,Inside jacket 1.6%,sample-151,33.15531615
438,140,180,3.88,150,103,0.484,0.14,6.60E-05,Inside jacket 1.6%,sample-1519,26.4506032
444,140,180,3.88,150,103,0.484,0.2,3.00E-05,Outside jacket 0.5%,sample-1524,3.845203161
450,140,180,3.88,150,103,1.79,0.14,3.00E-05,Outside jacket 0.5%,sample-1530,5.16334031
456,140,180,3.88,150,103,1.79,0.2,6.60E-05,Inside jacket 0.44%,sample-1538,0.412562505
462,140,180,3.88,150,250,0.484,0.2,3.00E-05,Inside jacket 0.44%,sample-1547,0.368025841
468,140,180,3.88,150,250,1.79,0.14,3.00E-05,Inside jacket 0.44%,sample-1553,0.433652263
474,140,180,3.88,150,250,1.79,0.2,3.00E-05,Inside jacket 0.44%,sample-1559,0.444269524
480,140,180,3.88,150,70,0.484,0.14,3.00E-05,Outside jacket 0.5%,sample-1566,8.960310392
486,140,180,3.88,150,70,0.484,0.2,3.00E-05,Inside jacket 0.44%,sample-1571,0.55023654
492,140,180,3.88,150,70,1.79,0.14,3.00E-05,Inside jacket 0.44%,sample-1577,0.388069819
498,140,180,3.88,150,70,1.79,0.2,3.00E-05,Inside jacket 1.6%,sample-1582,23.085224
504,140,180,3.88,70,103,0.484,0.14,3.00E-05,Inside jacket 1.6%,sample-1588,29.6847941
510,140,180,3.88,70,103,0.484,0.14,6.60E-05,Outside jacket 0.5%,sample-1593,11.38711592
516,100,180,3.128,150,103,1.79,0.14,3.00E-05,Inside jacket 1.6%,sample-16,32.3802597
522,140,180,3.88,70,103,1.79,0.14,6.60E-05,Inside jacket 0.44%,sample-1604,0.465456212
528,100,180,3.128,90,103,1.79,0.14,3.00E-05,Inside jacket 0.44%,sample-161,0.683403019
534,140,180,3.88,70,70,0.484,0.14,3.00E-05,Inside jacket 0.44%,sample-1637,0.378307165
540,140,180,3.88,70,70,0.484,0.2,3.00E-05,Inside jacket 1.6%,sample-1642,27.2610929
546,140,180,3.88,70,70,1.79,0.14,3.00E-05,Inside jacket 1.6%,sample-1648,37.16962538
552,140,180,3.88,70,70,1.79,0.14,6.60E-05,Outside jacket 0.5%,sample-1653,8.962780048
558,140,180,3.88,70,70,1.79,0.2,6.60E-05,Outside jacket 0.5%,sample-1659,9.11943728
564,140,180,3.88,90,103,0.484,0.14,6.60E-05,Inside jacket 0.44%,sample-1664,0.546542721
570,140,180,3.88,90,103,0.484,0.2,6.60E-05,Inside jacket 0.44%,sample-1670,0.450566325
576,140,180,3.88,90,103,1.79,0.14,6.60E-05,Inside jacket 0.44%,sample-1676,0.446313152
582,140,180,3.88,90,103,1.79,0.2,6.60E-05,Inside jacket 1.6%,sample-1681,24.8867131
588,140,180,3.88,90,250,0.484,0.14,6.60E-05,Inside jacket 1.6%,sample-1687,36.93138533
594,140,180,3.88,90,250,0.484,0.2,3.00E-05,Outside jacket 0.5%,sample-1692,5.178783647
600,140,180,3.88,90,250,1.79,0.14,3.00E-05,Outside jacket 0.5%,sample-1698,2.773847322
606,140,180,3.88,90,250,1.79,0.2,3.00E-05,Inside jacket 1.6%,sample-1702,30.7778559
612,140,180,3.88,90,70,0.484,0.14,3.00E-05,Inside jacket 1.6%,sample-1708,28.30819399
618,140,180,3.88,90,70,0.484,0.14,6.60E-05,Outside jacket 0.5%,sample-1713,10.02354857
624,140,180,3.88,90,70,0.484,0.2,6.60E-05,Outside jacket 0.5%,sample-1719,6.427425545
630,140,180,3.88,90,70,1.79,0.14,6.60E-05,Inside jacket 0.44%,sample-1724,0.467880437
636,100,180,3.128,90,250,0.484,0.14,3.00E-05,Inside jacket 0.44%,sample-173,0.886583321
642,140,260,3.128,150,103,0.484,0.14,6.60E-05,Inside jacket 1.6%,sample-1735,18.52730798
648,140,260,3.128,150,103,0.484,0.2,3.00E-05,Outside jacket 0.5%,sample-1740,5.114792574
654,140,260,3.128,150,103,1.79,0.14,6.60E-05,Inside jacket 0.44%,sample-1748,0.389370813
660,140,260,3.128,150,103,1.79,0.2,6.60E-05,Inside jacket 1.6%,sample-1753,14.75343236
666,140,260,3.128,150,250,0.484,0.14,6.60E-05,Inside jacket 1.6%,sample-1759,14.36603959
672,140,260,3.128,150,250,0.484,0.2,3.00E-05,Outside jacket 0.5%,sample-1764,0.664799024
678,100,180,3.128,90,250,0.484,0.14,6.60E-05,Outside jacket 0.5%,sample-177,5.243738869
684,140,260,3.128,150,250,1.79,0.2,3.00E-05,Inside jacket 0.44%,sample-1775,0.380370239
690,140,260,3.128,150,70,0.484,0.14,3.00E-05,Inside jacket 1.6%,sample-1780,28.31635841
696,140,260,3.128,150,70,0.484,0.2,3.00E-05,Inside jacket 1.6%,sample-1786,11.66932548
702,140,260,3.128,150,70,0.484,0.2,6.60E-05,Outside jacket 0.5%,sample-1791,3.803433643
708,140,260,3.128,150,70,1.79,0.14,6.60E-05,Outside jacket 0.5%,sample-1797,3.401325156
714,140,260,3.128,150,70,1.79,0.2,6.60E-05,Inside jacket 1.6%,sample-1801,10.03998436
720,140,260,3.128,70,103,0.484,0.14,6.60E-05,Inside jacket 1.6%,sample-1807,28.5070848
726,140,260,3.128,70,103,0.484,0.2,3.00E-05,Outside jacket 0.5%,sample-1812,4.259732271
732,140,260,3.128,70,103,1.79,0.14,3.00E-05,Outside jacket 0.5%,sample-1818,5.865944991
738,140,260,3.128,70,103,1.79,0.2,3.00E-05,Inside jacket 0.44%,sample-1823,0.509892065
744,100,180,3.128,90,250,1.79,0.14,3.00E-05,Inside jacket 1.6%,sample-184,23.05432145
750,140,260,3.128,90,250,0.484,0.2,3.00E-05,Outside jacket 0.5%,sample-1908,1.630631725
756,140,260,3.128,90,250,1.79,0.14,3.00E-05,Inside jacket 0.44%,sample-1913,0.786788666
762,140,260,3.128,90,250,1.79,0.2,3.00E-05,Inside jacket 0.44%,sample-1919,1.412332003
768,140,260,3.128,90,70,0.484,0.14,3.00E-05,Inside jacket 1.6%,sample-1924,23.07700212
774,100,180,3.128,90,250,1.79,0.2,6.60E-05,Inside jacket 1.6%,sample-193,28.46664628
780,140,260,3.128,90,70,0.484,0.2,6.60E-05,Outside jacket 0.5%,sample-1935,7.390574571
786,140,260,3.128,90,70,1.79,0.14,6.60E-05,Inside jacket 0.44%,sample-1940,0.601115042
792,140,260,3.128,90,70,1.79,0.2,6.60E-05,Inside jacket 0.44%,sample-1946,0.57445633
798,140,260,3.88,150,103,0.484,0.14,6.60E-05,Inside jacket 1.6%,sample-1951,27.63175745
804,140,260,3.88,150,103,0.484,0.2,6.60E-05,Inside jacket 1.6%,sample-1957,7.615040435
810,140,260,3.88,150,103,1.79,0.14,6.60E-05,Inside jacket 1.6%,sample-1963,20.27967484
816,140,260,3.88,150,103,1.79,0.2,6.60E-05,Inside jacket 1.6%,sample-1969,14.7844905
822,140,260,3.88,150,250,0.484,0.14,3.00E-05,Outside jacket 0.5%,sample-1974,1.158751032
828,100,180,3.128,90,70,0.484,0.14,3.00E-05,Outside jacket 0.5%,sample-198,8.191203099
834,140,260,3.88,150,250,1.79,0.14,3.00E-05,Inside jacket 0.44%,sample-1985,0.417594546
840,140,260,3.88,150,250,1.79,0.2,3.00E-05,Inside jacket 1.6%,sample-1990,7.16824412
846,140,260,3.88,150,70,0.484,0.14,3.00E-05,Inside jacket 1.6%,sample-1996,26.10737829
852,140,260,3.88,150,70,0.484,0.14,6.60E-05,Inside jacket 0.44%,sample-2000,0.388696019
858,140,260,3.88,150,70,0.484,0.2,6.60E-05,Inside jacket 0.44%,sample-2006,0.402783409
864,140,260,3.88,150,70,1.79,0.14,6.60E-05,Inside jacket 1.6%,sample-2011,23.7259615
870,140,260,3.88,150,70,1.79,0.2,6.60E-05,Inside jacket 1.6%,sample-2017,13.51340905
876,140,260,3.88,70,103,0.484,0.14,3.00E-05,Outside jacket 0.5%,sample-2022,7.605353358
882,140,260,3.88,70,103,0.484,0.2,3.00E-05,Outside jacket 0.5%,sample-2028,4.947650079
888,140,260,3.88,70,103,1.79,0.14,3.00E-05,Inside jacket 0.44%,sample-2033,0.642195185
894,140,260,3.88,70,103,1.79,0.2,3.00E-05,Inside jacket 0.44%,sample-2039,0.538312189
900,100,180,3.128,90,70,0.484,0.2,6.60E-05,Inside jacket 1.6%,sample-205,31.13825636
906,140,260,3.88,70,70,0.484,0.14,6.60E-05,Inside jacket 1.6%,sample-2071,32.93234307
912,140,260,3.88,70,70,0.484,0.2,6.60E-05,Inside jacket 1.6%,sample-2077,13.07326018
918,140,260,3.88,70,70,1.79,0.14,3.00E-05,Outside jacket 0.5%,sample-2082,8.153802876
924,140,260,3.88,70,70,1.79,0.2,3.00E-05,Outside jacket 0.5%,sample-2088,5.754235453
930,140,260,3.88,90,103,0.484,0.14,3.00E-05,Inside jacket 0.44%,sample-2093,0.553092584
936,140,260,3.88,90,103,0.484,0.2,3.00E-05,Inside jacket 0.44%,sample-2099,0.610247472
942,140,260,3.88,90,103,0.484,0.2,6.60E-05,Outside jacket 0.5%,sample-2103,3.799068963
948,140,260,3.88,90,103,1.79,0.14,6.60E-05,Outside jacket 0.5%,sample-2109,6.090503458
954,140,260,3.88,90,103,1.79,0.2,6.60E-05,Inside jacket 0.44%,sample-2114,0.573378471
960,100,180,3.128,90,70,1.79,0.14,6.60E-05,Inside jacket 0.44%,sample-212,0.643326226
966,140,260,3.88,90,250,0.484,0.2,6.60E-05,Inside jacket 1.6%,sample-2125,49.31471618
972,140,260,3.88,90,250,1.79,0.14,3.00E-05,Outside jacket 0.5%,sample-2130,1.790414928
978,140,260,3.88,90,250,1.79,0.2,3.00E-05,Outside jacket 0.5%,sample-2136,2.74076938
984,140,260,3.88,90,70,0.484,0.14,3.00E-05,Inside jacket 0.44%,sample-2141,0.669516852
990,140,260,3.88,90,70,0.484,0.2,3.00E-05,Inside jacket 0.44%,sample-2147,0.517085633
996,140,260,3.88,90,70,1.79,0.14,3.00E-05,Inside jacket 1.6%,sample-2152,17.95360668
1002,140,260,3.88,90,70,1.79,0.2,3.00E-05,Inside jacket 1.6%,sample-2158,15.25076065
1008,140,260,3.88,90,70,1.79,0.2,6.60E-05,Outside jacket 0.5%,sample-2163,6.391048465
1014,140,340,3.128,150,103,0.484,0.14,6.60E-05,Outside jacket 0.5%,sample-2169,0.540833835
1020,140,340,3.128,150,103,0.484,0.2,6.60E-05,Inside jacket 0.44%,sample-2174,0.392355816
1026,100,180,3.128,90,70,1.79,0.2,6.60E-05,Inside jacket 0.44%,sample-218,0.679217154
1032,140,340,3.128,150,103,1.79,0.2,6.60E-05,Inside jacket 1.6%,sample-2185,16.19803814
1038,140,340,3.128,150,250,0.484,0.14,3.00E-05,Outside jacket 0.5%,sample-2190,0.863483207
1044,140,340,3.128,150,250,0.484,0.2,3.00E-05,Outside jacket 0.5%,sample-2196,0.751926988
1050,140,340,3.128,150,250,1.79,0.14,3.00E-05,Inside jacket 1.6%,sample-2200,11.5265165
1056,140,340,3.128,150,250,1.79,0.2,3.00E-05,Inside jacket 1.6%,sample-2206,6.517620906
1062,140,340,3.128,150,250,1.79,0.2,6.60E-05,Outside jacket 0.5%,sample-2211,0.658432814
1068,140,340,3.128,150,70,0.484,0.14,6.60E-05,Outside jacket 0.5%,sample-2217,0.47449062
1074,140,340,3.128,150,70,0.484,0.2,6.60E-05,Inside jacket 0.44%,sample-2222,0.368581994
1080,140,340,3.128,150,70,1.79,0.14,6.60E-05,Inside jacket 0.44%,sample-2228,0.383042397
1086,140,340,3.128,150,70,1.79,0.2,6.60E-05,Inside jacket 1.6%,sample-2233,11.31570174
1092,140,340,3.128,70,103,0.484,0.14,6.60E-05,Inside jacket 1.6%,sample-2239,16.38690205
1098,140,340,3.128,70,103,0.484,0.2,3.00E-05,Outside jacket 0.5%,sample-2244,1.505631754
1104,100,180,3.88,150,103,0.484,0.14,6.60E-05,Outside jacket 0.5%,sample-225,3.061147815
1110,140,340,3.128,70,103,1.79,0.2,3.00E-05,Inside jacket 0.44%,sample-2255,0.519310089
1116,100,180,3.88,150,103,0.484,0.2,3.00E-05,Inside jacket 0.44%,sample-227,0.625577536
1122,140,340,3.128,70,70,0.484,0.14,6.60E-05,Inside jacket 0.44%,sample-2288,0.631770972
1128,140,340,3.128,70,70,0.484,0.2,6.60E-05,Inside jacket 1.6%,sample-2293,15.59651185
1134,140,340,3.128,70,70,1.79,0.14,6.60E-05,Inside jacket 1.6%,sample-2299,11.89883806
1140,140,340,3.128,70,70,1.79,0.2,3.00E-05,Inside jacket 0.44%,sample-2303,0.618447096
1146,140,340,3.128,90,103,0.484,0.14,3.00E-05,Inside jacket 0.44%,sample-2309,0.57633419
1152,140,340,3.128,90,103,0.484,0.2,3.00E-05,Inside jacket 1.6%,sample-2314,14.24413311
1158,100,180,3.88,150,103,1.79,0.14,3.00E-05,Inside jacket 1.6%,sample-232,36.96669024
1164,140,340,3.128,90,103,1.79,0.14,6.60E-05,Outside jacket 0.5%,sample-2325,3.126997993
1170,140,340,3.128,90,103,1.79,0.2,6.60E-05,Inside jacket 0.44%,sample-2330,0.52006544
1176,140,340,3.128,90,250,0.484,0.14,6.60E-05,Inside jacket 0.44%,sample-2336,1.306287182
1182,140,340,3.128,90,250,0.484,0.2,6.60E-05,Inside jacket 1.6%,sample-2341,24.25030828
1188,140,340,3.128,90,250,1.79,0.14,6.60E-05,Inside jacket 1.6%,sample-2347,42.92060799
1194,140,340,3.128,90,250,1.79,0.2,3.00E-05,Outside jacket 0.5%,sample-2352,12.5304446
1200,140,340,3.128,90,70,0.484,0.14,3.00E-05,Outside jacket 0.5%,sample-2358,7.097185336
1206,140,340,3.128,90,70,0.484,0.2,3.00E-05,Inside jacket 0.44%,sample-2363,0.623200167
1212,140,340,3.128,90,70,1.79,0.14,3.00E-05,Inside jacket 0.44%,sample-2369,0.508878096
1218,140,340,3.128,90,70,1.79,0.2,3.00E-05,Inside jacket 1.6%,sample-2374,8.513785515
1224,100,180,3.88,150,103,1.79,0.2,3.00E-05,Inside jacket 1.6%,sample-238,46.31307602
1230,140,340,3.88,150,103,0.484,0.14,6.60E-05,Outside jacket 0.5%,sample-2385,0.585928831
1236,140,340,3.88,150,103,0.484,0.2,6.60E-05,Inside jacket 0.44%,sample-2390,0.388115658
1242,140,340,3.88,150,103,1.79,0.14,6.60E-05,Inside jacket 0.44%,sample-2396,0.366975764
1248,140,340,3.88,150,103,1.79,0.2,3.00E-05,Outside jacket 0.5%,sample-2400,0.697465868
1254,140,340,3.88,150,250,0.484,0.14,3.00E-05,Outside jacket 0.5%,sample-2406,0.640027598
1260,140,340,3.88,150,250,0.484,0.2,3.00E-05,Inside jacket 0.44%,sample-2411,0.367962838
1266,140,340,3.88,150,250,1.79,0.14,3.00E-05,Inside jacket 0.44%,sample-2417,0.41042593
1272,140,340,3.88,150,250,1.79,0.2,3.00E-05,Inside jacket 1.6%,sample-2422,12.55521374
1278,140,340,3.88,150,70,0.484,0.14,3.00E-05,Inside jacket 1.6%,sample-2428,9.03234369
1284,140,340,3.88,150,70,0.484,0.14,6.60E-05,Outside jacket 0.5%,sample-2433,0.574666331
1290,140,340,3.88,150,70,0.484,0.2,6.60E-05,Outside jacket 0.5%,sample-2439,0.630840471
1296,140,340,3.88,150,70,1.79,0.14,6.60E-05,Inside jacket 0.44%,sample-2444,0.416139971
1302,100,180,3.88,150,250,0.484,0.14,3.00E-05,Inside jacket 0.44%,sample-245,0.908116743
1308,140,340,3.88,70,103,0.484,0.14,6.60E-05,Inside jacket 1.6%,sample-2455,13.10022707
1314,140,340,3.88,70,103,0.484,0.2,3.00E-05,Outside jacket 0.5%,sample-2460,1.387478447
1320,140,340,3.88,70,103,1.79,0.14,3.00E-05,Outside jacket 0.5%,sample-2466,5.428429844
1326,140,340,3.88,70,103,1.79,0.2,3.00E-05,Inside jacket 0.44%,sample-2471,0.523705274
1332,100,180,3.88,150,250,0.484,0.14,6.60E-05,Outside jacket 0.5%,sample-249,0.829192902
1338,140,340,3.88,70,70,0.484,0.14,6.60E-05,Inside jacket 1.6%,sample-2503,10.6962569
1344,140,340,3.88,70,70,0.484,0.2,6.60E-05,Inside jacket 1.6%,sample-2509,9.590318572
1350,140,340,3.88,70,70,1.79,0.14,3.00E-05,Outside jacket 0.5%,sample-2514,9.175343038
1356,100,180,3.88,150,250,0.484,0.2,3.00E-05,Outside jacket 0.5%,sample-252,0.976551866
1362,140,340,3.88,90,103,0.484,0.14,3.00E-05,Inside jacket 0.44%,sample-2525,0.746701713
1368,140,340,3.88,90,103,0.484,0.2,3.00E-05,Inside jacket 1.6%,sample-2530,13.5364777
1374,140,340,3.88,90,103,1.79,0.14,3.00E-05,Inside jacket 1.6%,sample-2536,11.61879204
1380,140,340,3.88,90,103,1.79,0.14,6.60E-05,Outside jacket 0.5%,sample-2541,2.606456571
1386,140,340,3.88,90,103,1.79,0.2,6.60E-05,Outside jacket 0.5%,sample-2547,1.124535398
1392,140,340,3.88,90,250,0.484,0.14,6.60E-05,Inside jacket 0.44%,sample-2552,1.301008505
1398,140,340,3.88,90,250,0.484,0.2,6.60E-05,Inside jacket 0.44%,sample-2558,1.511027587
1404,140,340,3.88,90,250,1.79,0.14,6.60E-05,Inside jacket 1.6%,sample-2563,40.34920911
1410,140,340,3.88,90,250,1.79,0.2,6.60E-05,Inside jacket 1.6%,sample-2569,19.90088566
1416,140,340,3.88,90,70,0.484,0.14,3.00E-05,Outside jacket 0.5%,sample-2574,8.281732709
1422,100,180,3.88,150,250,1.79,0.14,3.00E-05,Outside jacket 0.5%,sample-258,0.870531101
1428,140,340,3.88,90,70,1.79,0.14,3.00E-05,Inside jacket 0.44%,sample-2585,0.558804387
1434,140,340,3.88,90,70,1.79,0.2,3.00E-05,Inside jacket 1.6%,sample-2590,10.42700981
1440,180,180,3.128,150,103,0.484,0.14,3.00E-05,Inside jacket 1.6%,sample-2596,15.87644275
1446,180,180,3.128,150,103,0.484,0.14,6.60E-05,Inside jacket 0.44%,sample-2600,0.272894636
1452,180,180,3.128,150,103,0.484,0.2,6.60E-05,Inside jacket 0.44%,sample-2606,0.302245005
1458,180,180,3.128,150,103,1.79,0.14,6.60E-05,Inside jacket 1.6%,sample-2611,11.73209073
1464,180,180,3.128,150,103,1.79,0.2,6.60E-05,Inside jacket 1.6%,sample-2617,8.296583965
1470,180,180,3.128,150,250,0.484,0.14,3.00E-05,Outside jacket 0.5%,sample-2622,0.918733045
1476,180,180,3.128,150,250,0.484,0.2,3.00E-05,Outside jacket 0.5%,sample-2628,0.687239728
1482,180,180,3.128,150,250,1.79,0.14,3.00E-05,Inside jacket 0.44%,sample-2633,0.366370714
1488,180,180,3.128,150,250,1.79,0.2,3.00E-05,Inside jacket 0.44%,sample-2639,0.349279538
1494,180,180,3.128,150,70,0.484,0.14,3.00E-05,Inside jacket 1.6%,sample-2644,17.36157878
1500,100,180,3.88,150,250,1.79,0.2,6.60E-05,Inside jacket 1.6%,sample-265,42.21329883
1506,180,180,3.128,150,70,0.484,0.2,6.60E-05,Outside jacket 0.5%,sample-2655,5.052882966
1512,180,180,3.128,150,70,1.79,0.14,6.60E-05,Inside jacket 0.44%,sample-2660,0.334868111
1518,180,180,3.128,150,70,1.79,0.2,6.60E-05,Inside jacket 0.44%,sample-2666,0.328115912
1524,180,180,3.128,70,103,0.484,0.14,6.60E-05,Inside jacket 1.6%,sample-2671,20.66824633
1530,180,180,3.128,70,103,0.484,0.2,6.60E-05,Inside jacket 1.6%,sample-2677,17.03177378
1536,180,180,3.128,70,103,1.79,0.14,3.00E-05,Outside jacket 0.5%,sample-2682,6.836436859
1542,180,180,3.128,70,103,1.79,0.2,3.00E-05,Outside jacket 0.5%,sample-2688,5.997493486
1548,100,180,3.88,150,70,0.484,0.14,3.00E-05,Outside jacket 0.5%,sample-270,5.21806123
1554,100,180,3.88,150,70,0.484,0.14,6.60E-05,Inside jacket 0.44%,sample-272,0.595019173
1560,180,180,3.128,70,70,0.484,0.2,6.60E-05,Inside jacket 1.6%,sample-2725,16.82478741
1566,180,180,3.128,70,70,1.79,0.14,3.00E-05,Outside jacket 0.5%,sample-2730,15.38869388
1572,180,180,3.128,70,70,1.79,0.2,3.00E-05,Outside jacket 0.5%,sample-2736,6.02074219
1578,180,180,3.128,90,103,0.484,0.14,3.00E-05,Inside jacket 0.44%,sample-2741,0.412527929
1584,180,180,3.128,90,103,0.484,0.2,3.00E-05,Inside jacket 0.44%,sample-2747,0.536435443
1590,180,180,3.128,90,103,1.79,0.14,3.00E-05,Inside jacket 1.6%,sample-2752,13.49467942
1596,180,180,3.128,90,103,1.79,0.2,3.00E-05,Inside jacket 1.6%,sample-2758,15.60413374
1602,180,180,3.128,90,103,1.79,0.2,6.60E-05,Outside jacket 0.5%,sample-2763,5.237589259
1608,180,180,3.128,90,250,0.484,0.14,6.60E-05,Outside jacket 0.5%,sample-2769,7.917299188
1614,180,180,3.128,90,250,0.484,0.2,6.60E-05,Inside jacket 0.44%,sample-2774,3.977182961
1620,100,180,3.88,150,70,0.484,0.2,6.60E-05,Inside jacket 0.44%,sample-278,0.572554545
1626,180,180,3.128,90,250,1.79,0.2,6.60E-05,Inside jacket 1.6%,sample-2785,20.18134824
1632,180,180,3.128,90,70,0.484,0.14,3.00E-05,Outside jacket 0.5%,sample-2790,9.413324997
1638,180,180,3.128,90,70,0.484,0.2,3.00E-05,Outside jacket 0.5%,sample-2796,6.884760331
1644,180,180,3.128,90,70,1.79,0.14,3.00E-05,Inside jacket 1.6%,sample-2800,14.89589039
1650,180,180,3.128,90,70,1.79,0.2,3.00E-05,Inside jacket 1.6%,sample-2806,17.67611592
1656,180,180,3.128,90,70,1.79,0.2,6.60E-05,Outside jacket 0.5%,sample-2811,8.964751229
1662,180,180,3.88,150,103,0.484,0.14,6.60E-05,Outside jacket 0.5%,sample-2817,6.843287825
1668,180,180,3.88,150,103,0.484,0.2,6.60E-05,Inside jacket 0.44%,sample-2822,0.358420781
1674,180,180,3.88,150,103,1.79,0.14,6.60E-05,Inside jacket 0.44%,sample-2828,0.27296467
1680,180,180,3.88,150,103,1.79,0.2,6.60E-05,Inside jacket 1.6%,sample-2833,8.0599355
1686,180,180,3.88,150,250,0.484,0.14,6.60E-05,Inside jacket 1.6%,sample-2839,9.726291706
1692,180,180,3.88,150,250,0.484,0.2,3.00E-05,Outside jacket 0.5%,sample-2844,0.757618178
1698,100,180,3.88,150,70,1.79,0.14,6.60E-05,Outside jacket 0.5%,sample-285,10.00600383
1704,180,180,3.88,150,250,1.79,0.2,3.00E-05,Inside jacket 0.44%,sample-2855,0.320606654
1710,180,180,3.88,150,70,0.484,0.14,3.00E-05,Inside jacket 1.6%,sample-2860,18.37353651
1716,180,180,3.88,150,70,0.484,0.2,3.00E-05,Inside jacket 1.6%,sample-2866,6.307799693
1722,180,180,3.88,150,70,0.484,0.2,6.60E-05,Outside jacket 0.5%,sample-2871,5.51529678
1728,180,180,3.88,150,70,1.79,0.14,6.60E-05,Outside jacket 0.5%,sample-2877,8.488335663
1734,180,180,3.88,150,70,1.79,0.2,6.60E-05,Inside jacket 0.44%,sample-2882,0.340429446
1740,180,180,3.88,70,103,0.484,0.14,6.60E-05,Inside jacket 0.44%,sample-2888,0.396135086
1746,180,180,3.88,70,103,0.484,0.2,6.60E-05,Inside jacket 1.6%,sample-2893,17.99881398
1752,180,180,3.88,70,103,1.79,0.14,6.60E-05,Inside jacket 1.6%,sample-2899,10.69942295
1758,180,180,3.88,70,103,1.79,0.2,3.00E-05,Inside jacket 0.44%,sample-2903,0.385127792
1764,100,180,3.88,70,103,0.484,0.14,3.00E-05,Inside jacket 1.6%,sample-292,36.86255178
1770,180,180,3.88,70,70,0.484,0.14,6.60E-05,Inside jacket 0.44%,sample-2936,0.418866622
1776,180,180,3.88,70,70,0.484,0.2,6.60E-05,Inside jacket 1.6%,sample-2941,19.09701671
1782,180,180,3.88,70,70,1.79,0.14,6.60E-05,Inside jacket 1.6%,sample-2947,9.313411868
1788,180,180,3.88,70,70,1.79,0.2,3.00E-05,Outside jacket 0.5%,sample-2952,6.301875855
1794,180,180,3.88,90,103,0.484,0.14,3.00E-05,Outside jacket 0.5%,sample-2958,15.54885365
1800,180,180,3.88,90,103,0.484,0.2,3.00E-05,Inside jacket 0.44%,sample-2963,0.440012504
1806,180,180,3.88,90,103,1.79,0.14,3.00E-05,Inside jacket 0.44%,sample-2969,0.431989144
1812,180,180,3.88,90,103,1.79,0.2,3.00E-05,Inside jacket 1.6%,sample-2974,13.6302942
1818,100,180,3.88,70,103,0.484,0.2,3.00E-05,Inside jacket 1.6%,sample-298,31.36554401
1824,180,180,3.88,90,250,0.484,0.14,6.60E-05,Outside jacket 0.5%,sample-2985,4.028648979
1830,180,180,3.88,90,250,0.484,0.2,6.60E-05,Inside jacket 0.44%,sample-2990,5.747139886
1836,180,180,3.88,90,250,1.79,0.14,6.60E-05,Inside jacket 0.44%,sample-2996,0.753744259
1842,180,180,3.88,90,250,1.79,0.2,3.00E-05,Outside jacket 0.5%,sample-3000,4.73321501
1848,100,180,3.88,70,103,1.79,0.14,3.00E-05,Outside jacket 0.5%,sample-306,4.795894453
1854,100,180,3.88,70,103,1.79,0.2,3.00E-05,Inside jacket 0.44%,sample-311,0.770456773
1860,100,180,3.128,150,250,0.484,0.14,6.60E-05,Outside jacket 0.5%,sample-33,0.921371277
1866,100,180,3.88,70,70,0.484,0.14,6.60E-05,Inside jacket 0.44%,sample-344,0.913861256
1872,100,180,3.128,150,250,0.484,0.2,3.00E-05,Inside jacket 0.44%,sample-35,0.783213673
1878,100,180,3.88,70,70,1.79,0.14,6.60E-05,Inside jacket 1.6%,sample-355,41.3796886
1884,100,180,3.88,70,70,1.79,0.2,3.00E-05,Outside jacket 0.5%,sample-360,4.53285245
1890,100,180,3.88,90,103,0.484,0.14,3.00E-05,Outside jacket 0.5%,sample-366,7.25211539
1896,100,180,3.88,90,103,0.484,0.2,3.00E-05,Inside jacket 0.44%,sample-371,0.707081337
1902,100,180,3.88,90,103,1.79,0.14,3.00E-05,Inside jacket 0.44%,sample-377,0.733251156
1908,100,180,3.88,90,103,1.79,0.2,3.00E-05,Inside jacket 1.6%,sample-382,28.18341951
1914,100,180,3.88,90,250,0.484,0.14,3.00E-05,Inside jacket 1.6%,sample-388,30.20424911
1920,100,180,3.88,90,250,0.484,0.14,6.60E-05,Outside jacket 0.5%,sample-393,7.746622064
1926,100,180,3.88,90,250,0.484,0.2,6.60E-05,Outside jacket 0.5%,sample-399,4.710053456
1932,100,180,3.88,90,250,1.79,0.14,6.60E-05,Inside jacket 1.6%,sample-403,23.52767659
1938,100,180,3.88,90,250,1.79,0.2,6.60E-05,Inside jacket 1.6%,sample-409,29.52082997
1944,100,180,3.88,90,70,0.484,0.14,3.00E-05,Outside jacket 0.5%,sample-414,6.848661415
1950,100,180,3.128,150,250,1.79,0.14,3.00E-05,Outside jacket 0.5%,sample-42,0.833768808
1956,100,180,3.88,90,70,1.79,0.14,3.00E-05,Inside jacket 0.44%,sample-425,0.757643921
1962,100,180,3.88,90,70,1.79,0.2,3.00E-05,Inside jacket 1.6%,sample-430,43.11216071
1968,100,260,3.128,150,103,0.484,0.14,3.00E-05,Inside jacket 1.6%,sample-436,27.79783457
1974,100,260,3.128,150,103,0.484,0.14,6.60E-05,Outside jacket 0.5%,sample-441,1.062312769
1980,100,260,3.128,150,103,0.484,0.2,6.60E-05,Outside jacket 0.5%,sample-447,0.817767714
1986,100,260,3.128,150,103,1.79,0.14,6.60E-05,Inside jacket 0.44%,sample-452,0.519141866
1992,100,260,3.128,150,103,1.79,0.2,6.60E-05,Inside jacket 0.44%,sample-458,0.485941814
1998,100,260,3.128,150,250,0.484,0.14,6.60E-05,Inside jacket 1.6%,sample-463,24.61843512
2004,100,260,3.128,150,250,0.484,0.2,6.60E-05,Inside jacket 1.6%,sample-469,11.09461793
2010,100,260,3.128,150,250,1.79,0.14,3.00E-05,Outside jacket 0.5%,sample-474,0.750160673
2016,100,180,3.128,150,250,1.79,0.2,3.00E-05,Outside jacket 0.5%,sample-48,0.885133152
2022,100,260,3.128,150,70,0.484,0.14,3.00E-05,Inside jacket 0.44%,sample-485,0.747394833
2028,100,260,3.128,150,70,0.484,0.2,3.00E-05,Inside jacket 1.6%,sample-490,9.23606354
2034,100,260,3.128,150,70,1.79,0.14,3.00E-05,Inside jacket 1.6%,sample-496,46.41854913
2040,100,260,3.128,150,70,1.79,0.14,6.60E-05,Inside jacket 0.44%,sample-500,0.727322507
2046,100,260,3.128,150,70,1.79,0.2,6.60E-05,Inside jacket 0.44%,sample-506,0.488380943
2052,100,260,3.128,70,103,0.484,0.14,6.60E-05,Inside jacket 1.6%,sample-511,17.98161526
2058,100,260,3.128,70,103,0.484,0.2,6.60E-05,Inside jacket 1.6%,sample-517,12.90101986
2064,100,260,3.128,70,103,1.79,0.14,3.00E-05,Outside jacket 0.5%,sample-522,1.061192101
2070,100,260,3.128,70,103,1.79,0.2,3.00E-05,Outside jacket 0.5%,sample-528,1.068943816
2076,100,180,3.128,150,70,0.484,0.14,6.60E-05,Inside jacket 1.6%,sample-55,29.93992916
2082,100,260,3.128,70,70,0.484,0.14,6.60E-05,Inside jacket 0.44%,sample-560,0.72688491
2088,100,260,3.128,70,70,0.484,0.2,6.60E-05,Inside jacket 0.44%,sample-566,0.872844726
2094,100,260,3.128,70,70,1.79,0.14,6.60E-05,Inside jacket 1.6%,sample-571,27.42084926
2100,100,260,3.128,70,70,1.79,0.2,6.60E-05,Inside jacket 1.6%,sample-577,9.318581097
2106,100,260,3.128,90,103,0.484,0.14,3.00E-05,Outside jacket 0.5%,sample-582,1.442887114
2112,100,260,3.128,90,103,0.484,0.2,3.00E-05,Outside jacket 0.5%,sample-588,1.054048126
2118,100,260,3.128,90,103,1.79,0.14,3.00E-05,Inside jacket 0.44%,sample-593,0.74576789
2124,100,260,3.128,90,103,1.79,0.2,3.00E-05,Inside jacket 0.44%,sample-599,0.689411436
2130,100,260,3.128,90,103,1.79,0.2,6.60E-05,Outside jacket 0.5%,sample-603,0.835372235
2136,100,260,3.128,90,250,0.484,0.14,6.60E-05,Outside jacket 0.5%,sample-609,1.453350341
2142,100,260,3.128,90,250,0.484,0.2,6.60E-05,Inside jacket 0.44%,sample-614,1.562416927
2148,100,180,3.128,150,70,0.484,0.2,6.60E-05,Inside jacket 0.44%,sample-62,0.661184993
2154,100,260,3.128,90,250,1.79,0.2,6.60E-05,Inside jacket 1.6%,sample-625,25.73491121
2160,100,260,3.128,90,70,0.484,0.14,3.00E-05,Outside jacket 0.5%,sample-630,2.806250476
2166,100,260,3.128,90,70,0.484,0.2,3.00E-05,Outside jacket 0.5%,sample-636,1.998794984
2172,100,260,3.128,90,70,1.79,0.14,3.00E-05,Inside jacket 0.44%,sample-641,0.761680367
2178,100,260,3.128,90,70,1.79,0.2,3.00E-05,Inside jacket 0.44%,sample-647,0.691967948
2184,100,260,3.88,150,103,0.484,0.14,3.00E-05,Inside jacket 1.6%,sample-652,36.01568565
2190,100,260,3.88,150,103,0.484,0.2,3.00E-05,Inside jacket 1.6%,sample-658,6.307770659
2196,100,260,3.88,150,103,0.484,0.2,6.60E-05,Outside jacket 0.5%,sample-663,0.73432087
2202,100,260,3.88,150,103,1.79,0.14,6.60E-05,Outside jacket 0.5%,sample-669,0.972481709
2208,100,260,3.88,150,103,1.79,0.2,6.60E-05,Inside jacket 0.44%,sample-674,0.536638463
2214,100,180,3.128,150,70,1.79,0.14,6.60E-05,Inside jacket 0.44%,sample-68,0.576709232
2220,100,260,3.88,150,250,0.484,0.2,6.60E-05,Inside jacket 1.6%,sample-685,6.327035213
2226,100,260,3.88,150,250,1.79,0.14,3.00E-05,Outside jacket 0.5%,sample-690,0.832136373
2232,100,260,3.88,150,250,1.79,0.2,3.00E-05,Outside jacket 0.5%,sample-696,0.87460295
2238,100,260,3.88,150,70,0.484,0.14,3.00E-05,Inside jacket 1.6%,sample-700,40.6723094
2244,100,260,3.88,150,70,0.484,0.2,3.00E-05,Inside jacket 1.6%,sample-706,10.26948525
2250,100,260,3.88,150,70,0.484,0.2,6.60E-05,Outside jacket 0.5%,sample-711,0.801149989
2256,100,260,3.88,150,70,1.79,0.14,6.60E-05,Outside jacket 0.5%,sample-717,0.815663431
2262,100,260,3.88,150,70,1.79,0.2,6.60E-05,Inside jacket 0.44%,sample-722,0.496052765
2268,100,260,3.88,70,103,0.484,0.14,6.60E-05,Inside jacket 0.44%,sample-728,0.735769074
2274,100,260,3.88,70,103,0.484,0.2,6.60E-05,Inside jacket 1.6%,sample-733,12.8705457
2280,100,260,3.88,70,103,1.79,0.14,6.60E-05,Inside jacket 1.6%,sample-739,27.90339091
2286,100,260,3.88,70,103,1.79,0.2,3.00E-05,Outside jacket 0.5%,sample-744,0.996625583
2292,100,180,3.128,70,103,0.484,0.14,3.00E-05,Inside jacket 0.44%,sample-77,0.79756978
2298,100,260,3.88,70,70,0.484,0.14,6.60E-05,Outside jacket 0.5%,sample-777,5.777746096
2304,100,260,3.88,70,70,0.484,0.2,6.60E-05,Inside jacket 0.44%,sample-782,0.810383638
2310,100,260,3.88,70,70,1.79,0.14,6.60E-05,Inside jacket 0.44%,sample-788,0.741991435
2316,100,260,3.88,70,70,1.79,0.2,6.60E-05,Inside jacket 1.6%,sample-793,8.340318556
2322,100,260,3.88,90,103,0.484,0.14,6.60E-05,Inside jacket 1.6%,sample-799,25.84476704
2328,100,260,3.88,90,103,0.484,0.2,3.00E-05,Inside jacket 0.44%,sample-803,0.699869813
2334,100,260,3.88,90,103,1.79,0.14,3.00E-05,Inside jacket 0.44%,sample-809,0.666226755
2340,100,260,3.88,90,103,1.79,0.2,3.00E-05,Inside jacket 1.6%,sample-814,11.82786385
2346,100,180,3.128,70,103,0.484,0.2,3.00E-05,Inside jacket 1.6%,sample-82,28.42062029
2352,100,260,3.88,90,250,0.484,0.14,6.60E-05,Outside jacket 0.5%,sample-825,1.660446597
2358,100,260,3.88,90,250,0.484,0.2,6.60E-05,Inside jacket 0.44%,sample-830,1.500028423
2364,100,260,3.88,90,250,1.79,0.14,6.60E-05,Inside jacket 0.44%,sample-836,1.221661287
2370,100,260,3.88,90,250,1.79,0.2,6.60E-05,Inside jacket 1.6%,sample-841,11.41481515
2376,100,260,3.88,90,70,0.484,0.14,6.60E-05,Inside jacket 1.6%,sample-847,31.19625006
2382,100,260,3.88,90,70,0.484,0.2,3.00E-05,Outside jacket 0.5%,sample-852,2.635822258
2388,100,260,3.88,90,70,1.79,0.14,3.00E-05,Outside jacket 0.5%,sample-858,1.155437968
2394,100,260,3.88,90,70,1.79,0.2,3.00E-05,Inside jacket 0.44%,sample-863,0.584480571
2400,100,340,3.128,150,103,0.484,0.14,3.00E-05,Inside jacket 0.44%,sample-869,0.614330861
2406,100,340,3.128,150,103,0.484,0.2,3.00E-05,Inside jacket 1.6%,sample-874,14.31800608
2412,100,180,3.128,70,103,1.79,0.14,3.00E-05,Inside jacket 1.6%,sample-88,29.72143213
2418,100,340,3.128,150,103,1.79,0.14,6.60E-05,Outside jacket 0.5%,sample-885,0.644039287
2424,100,340,3.128,150,103,1.79,0.2,6.60E-05,Inside jacket 0.44%,sample-890,0.819060474
2430,100,340,3.128,150,250,0.484,0.14,6.60E-05,Inside jacket 0.44%,sample-896,0.743782579
2436,100,340,3.128,150,250,0.484,0.2,3.00E-05,Outside jacket 0.5%,sample-900,1.057924573
2442,100,340,3.128,150,250,1.79,0.14,3.00E-05,Outside jacket 0.5%,sample-906,1.073306654
2448,100,340,3.128,150,250,1.79,0.2,3.00E-05,Inside jacket 0.44%,sample-911,0.637931644
2454,100,340,3.128,150,70,0.484,0.14,3.00E-05,Inside jacket 0.44%,sample-917,0.53213029
2460,100,340,3.128,150,70,0.484,0.2,3.00E-05,Inside jacket 1.6%,sample-922,8.555076395
2466,100,340,3.128,150,70,1.79,0.14,3.00E-05,Inside jacket 1.6%,sample-928,17.72627723
2472,100,340,3.128,150,70,1.79,0.14,6.60E-05,Outside jacket 0.5%,sample-933,0.642098621
2478,100,340,3.128,150,70,1.79,0.2,6.60E-05,Outside jacket 0.5%,sample-939,0.629556734
2484,100,340,3.128,70,103,0.484,0.14,6.60E-05,Inside jacket 0.44%,sample-944,0.864192551
2490,100,180,3.128,70,103,1.79,0.2,3.00E-05,Inside jacket 0.44%,sample-95,0.806748949
2496,100,340,3.128,70,103,1.79,0.14,6.60E-05,Inside jacket 1.6%,sample-955,19.97006976
2502,100,340,3.128,70,103,1.79,0.2,3.00E-05,Outside jacket 0.5%,sample-960,1.30782368
2508,100,340,3.128,70,70,0.484,0.14,3.00E-05,Inside jacket 1.6%,sample-988,15.11723551
2514,100,340,3.128,70,70,0.484,0.14,6.60E-05,Outside jacket 0.5%,sample-993,1.08861207
2520,100,340,3.128,70,70,0.484,0.2,6.60E-05,Outside jacket 0.5%,sample-999,1.030888782
2526,180,180,3.88,90,70,0.484,0.14,3.00E-05,Outside jacket 0.5%,sample-3006,9.983502522
2532,180,180,3.88,90,70,0.484,0.2,3.00E-05,Outside jacket 0.5%,sample-3012,6.235590001
2538,180,180,3.88,90,70,1.79,0.14,3.00E-05,Outside jacket 0.5%,sample-3018,7.094479259
2544,180,180,3.88,90,70,1.79,0.2,3.00E-05,Outside jacket 0.5%,sample-3024,6.421258416
2550,180,260,3.128,150,103,0.484,0.14,3.00E-05,Outside jacket 0.5%,sample-3030,5.251262928
2556,180,260,3.128,150,103,0.484,0.2,3.00E-05,Outside jacket 0.5%,sample-3036,3.774295424
2562,180,260,3.128,150,103,1.79,0.14,3.00E-05,Outside jacket 0.5%,sample-3042,4.472123419
2568,180,260,3.128,150,103,1.79,0.2,3.00E-05,Outside jacket 0.5%,sample-3048,3.174228659
2574,180,260,3.128,150,250,0.484,0.14,3.00E-05,Outside jacket 0.5%,sample-3054,1.032207615
2580,180,260,3.128,150,250,0.484,0.2,3.00E-05,Outside jacket 0.5%,sample-3060,0.76410108
2586,180,260,3.128,150,250,1.79,0.14,3.00E-05,Outside jacket 0.5%,sample-3066,0.70234882
2592,180,260,3.128,150,250,1.79,0.2,3.00E-05,Outside jacket 0.5%,sample-3072,0.704646604
2598,180,260,3.128,150,70,0.484,0.14,3.00E-05,Outside jacket 0.5%,sample-3078,5.481678113
2604,180,260,3.128,150,70,0.484,0.2,3.00E-05,Outside jacket 0.5%,sample-3084,3.745748453
2610,180,260,3.128,150,70,1.79,0.14,3.00E-05,Outside jacket 0.5%,sample-3090,4.920900698
2616,180,260,3.128,150,70,1.79,0.2,3.00E-05,Outside jacket 0.5%,sample-3096,5.592063019
2622,180,260,3.128,70,103,0.484,0.14,3.00E-05,Outside jacket 0.5%,sample-3102,11.16023793
2628,180,260,3.128,70,103,0.484,0.2,3.00E-05,Outside jacket 0.5%,sample-3108,6.841189599
2634,180,260,3.128,70,103,1.79,0.14,3.00E-05,Outside jacket 0.5%,sample-3114,9.518223531
2640,180,260,3.128,70,103,1.79,0.2,3.00E-05,Outside jacket 0.5%,sample-3120,4.226272861
2646,180,260,3.128,70,70,0.484,0.14,3.00E-05,Outside jacket 0.5%,sample-3150,9.152431242
2652,180,260,3.128,70,70,0.484,0.2,3.00E-05,Outside jacket 0.5%,sample-3156,8.406998451
2658,180,260,3.128,70,70,1.79,0.14,3.00E-05,Outside jacket 0.5%,sample-3162,9.682606159
2664,180,260,3.128,70,70,1.79,0.2,3.00E-05,Outside jacket 0.5%,sample-3168,7.055458537
2670,180,260,3.128,90,103,0.484,0.14,3.00E-05,Outside jacket 0.5%,sample-3174,9.262333346
2676,180,260,3.128,90,103,0.484,0.2,3.00E-05,Outside jacket 0.5%,sample-3180,5.046392529
2682,180,260,3.128,90,103,1.79,0.14,3.00E-05,Outside jacket 0.5%,sample-3186,9.910353349
2688,180,260,3.128,90,103,1.79,0.2,3.00E-05,Outside jacket 0.5%,sample-3192,4.105174889
2694,180,260,3.128,90,250,0.484,0.14,3.00E-05,Outside jacket 0.5%,sample-3198,5.10574007
2700,180,260,3.128,90,250,0.484,0.2,3.00E-05,Outside jacket 0.5%,sample-3204,7.723229439
2706,180,260,3.128,90,250,1.79,0.14,3.00E-05,Outside jacket 0.5%,sample-3210,4.250932717
2712,180,260,3.128,90,250,1.79,0.2,3.00E-05,Outside jacket 0.5%,sample-3216,4.183515839
2718,180,260,3.128,90,70,0.484,0.14,3.00E-05,Outside jacket 0.5%,sample-3222,9.029483746
2724,180,260,3.128,90,70,0.484,0.2,3.00E-05,Outside jacket 0.5%,sample-3228,5.13520602
2730,180,260,3.128,90,70,1.79,0.14,3.00E-05,Outside jacket 0.5%,sample-3234,9.220810306
2736,180,260,3.128,90,70,1.79,0.2,3.00E-05,Outside jacket 0.5%,sample-3240,7.176993329
2742,180,260,3.88,150,103,0.484,0.14,3.00E-05,Outside jacket 0.5%,sample-3246,5.204798363
2748,180,260,3.88,150,103,0.484,0.2,3.00E-05,Outside jacket 0.5%,sample-3252,3.048216633
2754,180,260,3.88,150,103,1.79,0.14,3.00E-05,Outside jacket 0.5%,sample-3258,4.517702565
2760,180,260,3.88,150,103,1.79,0.2,3.00E-05,Outside jacket 0.5%,sample-3264,2.633641022
2766,180,260,3.88,150,250,0.484,0.14,3.00E-05,Outside jacket 0.5%,sample-3270,0.991983586
2772,180,260,3.88,150,250,0.484,0.2,3.00E-05,Outside jacket 0.5%,sample-3276,0.671513658
2778,180,260,3.88,150,250,1.79,0.14,3.00E-05,Outside jacket 0.5%,sample-3282,0.766159477
2784,180,260,3.88,150,250,1.79,0.2,3.00E-05,Outside jacket 0.5%,sample-3288,0.688291732
2790,180,260,3.88,150,70,0.484,0.14,3.00E-05,Outside jacket 0.5%,sample-3294,6.009695944
2796,180,260,3.88,150,70,0.484,0.2,3.00E-05,Outside jacket 0.5%,sample-3300,3.823690418
2802,180,260,3.88,150,70,1.79,0.14,3.00E-05,Outside jacket 0.5%,sample-3306,4.873300803
2808,180,260,3.88,150,70,1.79,0.2,3.00E-05,Outside jacket 0.5%,sample-3312,5.490953527
2814,180,260,3.88,70,103,0.484,0.14,3.00E-05,Outside jacket 0.5%,sample-3318,9.699911048
2820,180,260,3.88,70,103,0.484,0.2,3.00E-05,Outside jacket 0.5%,sample-3324,5.622713556
2826,180,260,3.88,70,103,1.79,0.14,3.00E-05,Outside jacket 0.5%,sample-3330,8.831040063
2832,180,260,3.88,70,103,1.79,0.2,3.00E-05,Outside jacket 0.5%,sample-3336,4.120204057
2838,180,260,3.88,70,70,0.484,0.14,3.00E-05,Outside jacket 0.5%,sample-3366,9.4916072
2844,180,260,3.88,70,70,0.484,0.2,3.00E-05,Outside jacket 0.5%,sample-3372,6.767756391
2850,180,260,3.88,70,70,1.79,0.14,3.00E-05,Outside jacket 0.5%,sample-3378,15.56793143
2856,180,260,3.88,70,70,1.79,0.2,3.00E-05,Outside jacket 0.5%,sample-3384,6.321054599
2862,180,260,3.88,90,103,0.484,0.14,3.00E-05,Outside jacket 0.5%,sample-3390,9.734420746
2868,180,260,3.88,90,103,0.484,0.2,3.00E-05,Outside jacket 0.5%,sample-3396,5.797960208
2874,180,260,3.88,90,103,1.79,0.14,3.00E-05,Outside jacket 0.5%,sample-3402,9.308327835
2880,180,260,3.88,90,103,1.79,0.2,3.00E-05,Outside jacket 0.5%,sample-3408,4.445772088
2886,180,260,3.88,90,250,0.484,0.14,3.00E-05,Outside jacket 0.5%,sample-3414,4.066769354
2892,180,260,3.88,90,250,0.484,0.2,3.00E-05,Outside jacket 0.5%,sample-3420,4.588909434
2898,180,260,3.88,90,250,1.79,0.14,3.00E-05,Outside jacket 0.5%,sample-3426,3.385215353
2904,180,260,3.88,90,250,1.79,0.2,3.00E-05,Outside jacket 0.5%,sample-3432,4.411302912
2910,180,260,3.88,90,70,0.484,0.14,3.00E-05,Outside jacket 0.5%,sample-3438,11.70448111
2916,180,260,3.88,90,70,0.484,0.2,3.00E-05,Outside jacket 0.5%,sample-3444,5.234025159
2922,180,260,3.88,90,70,1.79,0.14,3.00E-05,Outside jacket 0.5%,sample-3450,11.34291772
2928,180,260,3.88,90,70,1.79,0.2,3.00E-05,Outside jacket 0.5%,sample-3456,6.143876727
2934,180,340,3.128,150,103,0.484,0.14,3.00E-05,Outside jacket 0.5%,sample-3462,6.563987902
2940,180,340,3.128,150,103,0.484,0.2,3.00E-05,Outside jacket 0.5%,sample-3468,2.083621198
2946,180,340,3.128,150,103,1.79,0.14,3.00E-05,Outside jacket 0.5%,sample-3474,4.383891184
2952,180,340,3.128,150,103,1.79,0.2,3.00E-05,Outside jacket 0.5%,sample-3480,0.422025954
2958,180,340,3.128,150,250,0.484,0.14,3.00E-05,Outside jacket 0.5%,sample-3486,1.076139274
2964,180,340,3.128,150,250,0.484,0.2,3.00E-05,Outside jacket 0.5%,sample-3492,0.818194267
2970,180,340,3.128,150,250,1.79,0.14,3.00E-05,Outside jacket 0.5%,sample-3498,0.790468381
2976,180,340,3.128,150,250,1.79,0.2,3.00E-05,Outside jacket 0.5%,sample-3504,0.658685895
2982,180,340,3.128,150,70,0.484,0.14,3.00E-05,Outside jacket 0.5%,sample-3510,5.180138695
2988,180,340,3.128,150,70,0.484,0.2,3.00E-05,Outside jacket 0.5%,sample-3516,2.617098028
2994,180,340,3.128,150,70,1.79,0.14,3.00E-05,Outside jacket 0.5%,sample-3522,3.255743302
3000,180,340,3.128,150,70,1.79,0.2,3.00E-05,Outside jacket 0.5%,sample-3528,2.042735989
3006,180,340,3.128,70,103,0.484,0.14,3.00E-05,Outside jacket 0.5%,sample-3534,10.28258831
3012,180,340,3.128,70,103,0.484,0.2,3.00E-05,Outside jacket 0.5%,sample-3540,6.079542846
3018,180,340,3.128,70,103,1.79,0.14,3.00E-05,Outside jacket 0.5%,sample-3546,9.562915155
3024,180,340,3.128,70,103,1.79,0.2,3.00E-05,Outside jacket 0.5%,sample-3552,1.246375228
3030,180,340,3.128,70,70,0.484,0.14,3.00E-05,Outside jacket 0.5%,sample-3582,7.993288031
3036,180,340,3.128,70,70,0.484,0.2,3.00E-05,Outside jacket 0.5%,sample-3588,5.481290328
3042,180,340,3.128,70,70,1.79,0.14,3.00E-05,Outside jacket 0.5%,sample-3594,9.060708629
3048,180,340,3.128,70,70,1.79,0.2,3.00E-05,Outside jacket 0.5%,sample-3600,6.734653633
3054,180,340,3.128,90,103,0.484,0.14,3.00E-05,Outside jacket 0.5%,sample-3606,6.857020046
3060,180,340,3.128,90,103,0.484,0.2,3.00E-05,Outside jacket 0.5%,sample-3612,4.615369464
3066,180,340,3.128,90,103,1.79,0.14,3.00E-05,Outside jacket 0.5%,sample-3618,5.86492737
3072,180,340,3.128,90,103,1.79,0.2,3.00E-05,Outside jacket 0.5%,sample-3624,1.886860495
3078,180,340,3.128,90,250,0.484,0.14,3.00E-05,Outside jacket 0.5%,sample-3630,4.591305063
3084,180,340,3.128,90,250,0.484,0.2,3.00E-05,Outside jacket 0.5%,sample-3636,9.535260819
3090,180,340,3.128,90,250,1.79,0.14,3.00E-05,Outside jacket 0.5%,sample-3642,4.261521941
3096,180,340,3.128,90,250,1.79,0.2,3.00E-05,Outside jacket 0.5%,sample-3648,5.240720924
3102,180,340,3.128,90,70,0.484,0.14,3.00E-05,Outside jacket 0.5%,sample-3654,8.491142459
3108,180,340,3.128,90,70,0.484,0.2,3.00E-05,Outside jacket 0.5%,sample-3660,5.776680238
3114,180,340,3.128,90,70,1.79,0.14,3.00E-05,Outside jacket 0.5%,sample-3666,14.1582231
3120,180,340,3.128,90,70,1.79,0.2,3.00E-05,Outside jacket 0.5%,sample-3672,4.864927028
3126,180,340,3.88,150,103,0.484,0.14,3.00E-05,Outside jacket 0.5%,sample-3678,5.523306964
3132,180,340,3.88,150,103,0.484,0.2,3.00E-05,Outside jacket 0.5%,sample-3684,1.956671315
3138,180,340,3.88,150,103,1.79,0.14,3.00E-05,Outside jacket 0.5%,sample-3690,4.231203069
3144,180,340,3.88,150,103,1.79,0.2,3.00E-05,Outside jacket 0.5%,sample-3696,0.516287445
3150,180,340,3.88,150,250,0.484,0.14,3.00E-05,Outside jacket 0.5%,sample-3702,1.342360738
3156,180,340,3.88,150,250,0.484,0.2,3.00E-05,Outside jacket 0.5%,sample-3708,0.822498909
3162,180,340,3.88,150,250,1.79,0.14,3.00E-05,Outside jacket 0.5%,sample-3714,0.812229005
3168,180,340,3.88,150,250,1.79,0.2,3.00E-05,Outside jacket 0.5%,sample-3720,0.639624618
3174,180,340,3.88,150,70,0.484,0.14,3.00E-05,Outside jacket 0.5%,sample-3726,4.847709505
3180,180,340,3.88,150,70,0.484,0.2,3.00E-05,Outside jacket 0.5%,sample-3732,3.490565598
3186,180,340,3.88,150,70,1.79,0.14,3.00E-05,Outside jacket 0.5%,sample-3738,3.319346881
3192,180,340,3.88,150,70,1.79,0.2,3.00E-05,Outside jacket 0.5%,sample-3744,2.04798884
3198,180,340,3.88,70,103,0.484,0.14,3.00E-05,Outside jacket 0.5%,sample-3750,9.364815931
3204,180,340,3.88,70,103,0.484,0.2,3.00E-05,Outside jacket 0.5%,sample-3756,5.799593614
3210,180,340,3.88,70,103,1.79,0.14,3.00E-05,Outside jacket 0.5%,sample-3762,6.719089254
3216,180,340,3.88,70,103,1.79,0.2,3.00E-05,Outside jacket 0.5%,sample-3768,1.194167147
3222,180,340,3.88,70,70,0.484,0.14,3.00E-05,Outside jacket 0.5%,sample-3798,8.718100872
3228,180,340,3.88,70,70,0.484,0.2,3.00E-05,Outside jacket 0.5%,sample-3804,5.303284243
3234,180,340,3.88,70,70,1.79,0.14,3.00E-05,Outside jacket 0.5%,sample-3810,7.096655369
3240,180,340,3.88,70,70,1.79,0.2,3.00E-05,Outside jacket 0.5%,sample-3816,4.948844921
3246,180,340,3.88,90,103,0.484,0.14,3.00E-05,Outside jacket 0.5%,sample-3822,7.23776513
3252,180,340,3.88,90,103,0.484,0.2,3.00E-05,Outside jacket 0.5%,sample-3828,4.259819055
3258,180,340,3.88,90,103,1.79,0.14,3.00E-05,Outside jacket 0.5%,sample-3834,6.587596293
3264,180,340,3.88,90,103,1.79,0.2,3.00E-05,Outside jacket 0.5%,sample-3840,1.80240017
3270,180,340,3.88,90,250,0.484,0.14,3.00E-05,Outside jacket 0.5%,sample-3846,1.954811333
3276,180,340,3.88,90,250,0.484,0.2,3.00E-05,Outside jacket 0.5%,sample-3852,5.616070889
3282,180,340,3.88,90,250,1.79,0.14,3.00E-05,Outside jacket 0.5%,sample-3858,4.984921038
3288,180,340,3.88,90,250,1.79,0.2,3.00E-05,Outside jacket 0.5%,sample-3864,3.031358923
3294,180,340,3.88,90,70,0.484,0.14,3.00E-05,Outside jacket 0.5%,sample-3870,14.08450706
3300,180,340,3.88,90,70,0.484,0.2,3.00E-05,Outside jacket 0.5%,sample-3876,5.152678026
3306,180,340,3.88,90,70,1.79,0.14,3.00E-05,Outside jacket 0.5%,sample-3882,12.24583112
3312,180,340,3.88,90,70,1.79,0.2,3.00E-05,Outside jacket 0.5%,sample-3888,4.890496962
3315,180,340,3.88,90,70,1.79,0.2,6.60E-05,Outside jacket 0.5%,sample-3891,6.03408853